{"trial_id": "1", "hyperparameters": {"space": [{"class_name": "Int", "config": {"name": "units_1", "default": null, "conditions": [], "min_value": 32, "max_value": 2048, "step": 32, "sampling": "linear"}}, {"class_name": "Int", "config": {"name": "units_2", "default": null, "conditions": [], "min_value": 32, "max_value": 2048, "step": 32, "sampling": "linear"}}, {"class_name": "Int", "config": {"name": "units_3", "default": null, "conditions": [], "min_value": 32, "max_value": 2048, "step": 32, "sampling": "linear"}}, {"class_name": "Int", "config": {"name": "units_4", "default": null, "conditions": [], "min_value": 32, "max_value": 2048, "step": 32, "sampling": "linear"}}, {"class_name": "Int", "config": {"name": "units_5", "default": null, "conditions": [], "min_value": 32, "max_value": 2048, "step": 32, "sampling": "linear"}}], "values": {"units_1": 1280, "units_2": 1280, "units_3": 736, "units_4": 704, "units_5": 96}}, "metrics": {"metrics": {}}, "score": null, "best_step": 0, "status": "FAILED", "message": "Traceback (most recent call last):\n  File \"C:\\Users\\Admin\\miniconda3\\envs\\Data\\lib\\site-packages\\keras_tuner\\src\\engine\\base_tuner.py\", line 273, in _try_run_and_update_trial\n    self._run_and_update_trial(trial, *fit_args, **fit_kwargs)\n  File \"C:\\Users\\Admin\\miniconda3\\envs\\Data\\lib\\site-packages\\keras_tuner\\src\\engine\\base_tuner.py\", line 238, in _run_and_update_trial\n    results = self.run_trial(trial, *fit_args, **fit_kwargs)\n  File \"C:\\Users\\Admin\\miniconda3\\envs\\Data\\lib\\site-packages\\keras_tuner\\src\\engine\\tuner.py\", line 314, in run_trial\n    obj_value = self._build_and_fit_model(trial, *args, **copied_kwargs)\n  File \"C:\\Users\\Admin\\miniconda3\\envs\\Data\\lib\\site-packages\\keras_tuner\\src\\engine\\tuner.py\", line 233, in _build_and_fit_model\n    results = self.hypermodel.fit(hp, model, *args, **kwargs)\n  File \"C:\\Users\\Admin\\miniconda3\\envs\\Data\\lib\\site-packages\\keras_tuner\\src\\engine\\hypermodel.py\", line 149, in fit\n    return model.fit(*args, **kwargs)\n  File \"C:\\Users\\Admin\\miniconda3\\envs\\Data\\lib\\site-packages\\keras\\utils\\traceback_utils.py\", line 70, in error_handler\n    raise e.with_traceback(filtered_tb) from None\n  File \"C:\\Users\\Admin\\AppData\\Local\\Temp\\__autograph_generated_filetdb42jw9.py\", line 15, in tf__train_function\n    retval_ = ag__.converted_call(ag__.ld(step_function), (ag__.ld(self), ag__.ld(iterator)), None, fscope)\nValueError: in user code:\n\n    File \"C:\\Users\\Admin\\miniconda3\\envs\\Data\\lib\\site-packages\\keras\\engine\\training.py\", line 1160, in train_function  *\n        return step_function(self, iterator)\n    File \"C:\\Users\\Admin\\miniconda3\\envs\\Data\\lib\\site-packages\\keras\\engine\\training.py\", line 1146, in step_function  **\n        outputs = model.distribute_strategy.run(run_step, args=(data,))\n    File \"C:\\Users\\Admin\\miniconda3\\envs\\Data\\lib\\site-packages\\keras\\engine\\training.py\", line 1135, in run_step  **\n        outputs = model.train_step(data)\n    File \"C:\\Users\\Admin\\miniconda3\\envs\\Data\\lib\\site-packages\\keras\\engine\\training.py\", line 993, in train_step\n        y_pred = self(x, training=True)\n    File \"C:\\Users\\Admin\\miniconda3\\envs\\Data\\lib\\site-packages\\keras\\utils\\traceback_utils.py\", line 70, in error_handler\n        raise e.with_traceback(filtered_tb) from None\n    File \"C:\\Users\\Admin\\miniconda3\\envs\\Data\\lib\\site-packages\\keras\\engine\\input_spec.py\", line 295, in assert_input_compatibility\n        raise ValueError(\n\n    ValueError: Input 0 of layer \"sequential\" is incompatible with the layer: expected shape=(None, 2), found shape=(None, 42)\n\n"}